Workbook

Sheet 2026-01-01 to 2026-01-31
A1: SLERP.
AJ2: Slerp Limited (10222686)
A7: STATEMENT - WING SHACK CO
A8: January 1 to January 31
A9: Generated on: 14 February 2026
A10: Summary | M10: Order Summary - Count of Transactions by Type (after refunds)
B11: Gross Transaction Value (before refunds) | C11: =H90+H101+H105
B12: Gross Transaction Value (after refunds) | C12: =I90+I105 | N12: Pickup | O12: Delivery | P12: Total
B13: Fees & Charges | M13: ASAP | N13: =COUNTIFS(D21:D89, "Pickup", E21:E89, "ASAP") | O13: =COUNTIFS(D21:D89, "Delivery", E21:E89, "ASAP") | P13: =N13+O13
B14: Slerp Commissions (inc. VAT) | C14: =AF90+AF105 | M14: Scheduled Same-Day | N14: =COUNTIFS(D21:D89, "Pickup", E21:E89, "Scheduled same day") | O14: =COUNTIFS(D21:D89, "Delivery", E21:E89, "Scheduled same day") | P14: =N14+O14
B15: Slerp Courier Partner Fees (inc. VAT) | C15: =S90+S105 | M15: Pre-Order | N15: =COUNTIFS(D21:D89, "Pickup", E21:E89, "Preorder") | O15: =COUNTIFS(D21:D89, "Delivery", E21:E89, "Preorder") | P15: =N15+O15
B16: Payment Fees | C16: =AH90+AH101+AH105 | M16: Total | N16: =SUM(N13:N15) | O16: =SUM(O13:O15) | P16: =SUM(P13:P15)
B17: Net Payable | C17: =C12+SUM(C14:C16)
A19: Completed orders
A20: Order Date | B20: Fulfillment date | C20: Location name | D20: Fulfillment type | E20: Order type | F20: Status | G20: Slerp ref (Id) | H20: Gross transaction value | I20: Gross Transaction value (after refunds) | J20: Product total | K20: Product VAT component | L20: Product discount applied | M20: Product total after discounts (GMV)** | N20: Gifting charge | O20: Additional store fee | P20: VAT component of Additional store fee | Q20: Tips | R20: Refunds | S20: (A) Slerp Courier Partner Quoted Courier Fee Including Vat | T20: VAT component of Slerp Courier Partner Quoted Courier Fee | U20: Self-delivery Fee / Self-organised Fee including VAT | V20: VAT component of Self-delivery / Self-organised fee | W20: Delivery fees (charged to customer) pre-discount applied | X20: Delivery Subsidisation (charged to partner) pre-discount applied | Y20: Discount code | Z20: Delivery fee discount applied | AA20: Tiered Delivery pricing percent % | AB20: Tiered Delivery actual | AC20: Delivery fees (charged to customer) post-discount applied | AD20: VAT component of Delivery fees (charged to customer) post-discount applied | AE20: Delivery Subsidisation (charged to partner) post-discount applied | AF20: (B) Slerp Commission including VAT | AG20: VAT component of Slerp Commission | AH20: (C) Payment fee | AI20: Total Captured by Slerp (A) + (B) + (C) | AJ20: Notes | AK20: Courier reference | AL20: Stripe payment reference | AM20: Balance transaction (Id) | AN20: Courier Type
A21: 02/01/2026 | B21: 02/01/2026 | C21: Loughton | D21: Pickup | E21: Scheduled same day | F21: fulfilled | G21: AQGDP4 | H21: 18.45 | I21: 18.45 | J21: 18.45 | K21: 0 | L21: 0 | M21: 18.45 | N21: 0 | O21: 0 | P21: 0 | Q21: 0 | R21: 0 | S21: 0 | T21: 0 | U21: 0 | V21: 0 | W21: 0 | X21: 0 | Z21: 0 | AA21: 0 | AB21: 0 | AC21: 0 | AD21: 0 | AE21: 0 | AF21: -4.43 | AG21: 0.74 | AH21: -0.74 | AI21: -5.17 | AL21: ch_3SlDeSGOs2bxG0Rw0OVBE8j3 | AM21: txn_3SlDeSGOs2bxG0Rw0Mp3wN7X | AN21: Self Delivery / 3PL
A22: 02/01/2026 | B22: 02/01/2026 | C22: Loughton | D22: Pickup | E22: ASAP | F22: fulfilled | G22: KTKFFZ | H22: 35.3 | I22: 35.3 | J22: 43.3 | K22: 0 | L22: -8 | M22: 35.3 | N22: 0 | O22: 0 | P22: 0 | Q22: 0 | R22: 0 | S22: 0 | T22: 0 | U22: 0 | V22: 0 | W22: 0 | X22: 0 | Y22: JAN2026 | Z22: 0 | AA22: 0 | AB22: 0 | AC22: 0 | AD22: 0 | AE22: 0 | AF22: -8.48 | AG22: 1.41 | AH22: -0.69 | AI22: -9.17 | AL22: ch_3SlE1tGOs2bxG0Rw03RpiBCN | AM22: txn_3SlE1tGOs2bxG0Rw0mOj4A0C | AN22: Self Delivery / 3PL
A23: 03/01/2026 | B23: 03/01/2026 | C23: Loughton | D23: Delivery | E23: Scheduled same day | F23: fulfilled | G23: 6XQPK5 | H23: 32.29 | I23: 32.29 | J23: 32.3 | K23: 0 | L23: -8 | M23: 24.3 | N23: 0 | O23: 0 | P23: 0 | Q23: 0 | R23: 0 | S23: -15.6 | T23: 2.6 | U23: 0 | V23: 0 | W23: 7.99 | X23: 7.61 | Y23: JAN2026 | Z23: 0 | AA23: 0 | AB23: 0 | AC23: 7.99 | AD23: 1.33 | AE23: 7.61 | AF23: -5.84 | AG23: 0.97 | AH23: -0.65 | AI23: -22.09 | AK23: 6992701b-6fcc-417c-b36d-e0d910f5feae | AL23: ch_3SlVvtGOs2bxG0Rw1AYNb4D9 | AM23: txn_3SlVvtGOs2bxG0Rw1h9DthKq | AN23: Slerp Courier Partner - Bike/Moped
A24: 04/01/2026 | B24: 04/01/2026 | C24: Loughton | D24: Pickup | E24: ASAP | F24: fulfilled | G24: G6W6Z4 | H24: 15.3 | I24: 15.3 | J24: 15.3 | K24: 0 | L24: 0 | M24: 15.3 | N24: 0 | O24: 0 | P24: 0 | Q24: 0 | R24: 0 | S24: 0 | T24: 0 | U24: 0 | V24: 0 | W24: 0 | X24: 0 | Z24: 0 | AA24: 0 | AB24: 0 | AC24: 0 | AD24: 0 | AE24: 0 | AF24: -3.68 | AG24: 0.61 | AH24: -0.41 | AI24: -4.09 | AL24: ch_3SlwFCGOs2bxG0Rw0F1XpcsO | AM24: txn_3SlwFCGOs2bxG0Rw0OCfxso9 | AN24: Self Delivery / 3PL
A25: 05/01/2026 | B25: 05/01/2026 | C25: Loughton | D25: Delivery | E25: ASAP | F25: fulfilled | G25: J6V4CK | H25: 33.49 | I25: 33.49 | J25: 30.5 | K25: 0 | L25: 0 | M25: 30.5 | N25: 0 | O25: 0 | P25: 0 | Q25: 0 | R25: 0 | S25: -8.82 | T25: 1.47 | U25: 0 | V25: 0 | W25: 2.99 | X25: 5.83 | Z25: 0 | AA25: 0 | AB25: 0 | AC25: 2.99 | AD25: 0.5 | AE25: 5.83 | AF25: -7.32 | AG25: 1.22 | AH25: -0.67 | AI25: -16.81 | AK25: 879abacc-29de-4a61-9910-175a2998e24c | AL25: ch_3SmIxyGOs2bxG0Rw1pmHFmZ1 | AM25: txn_3SmIxyGOs2bxG0Rw17TIukLs | AN25: Slerp Courier Partner - Bike/Moped
A26: 05/01/2026 | B26: 05/01/2026 | C26: Loughton | D26: Pickup | E26: ASAP | F26: fulfilled | G26: GT2CD6 | H26: 14 | I26: 14 | J26: 19 | K26: 0 | L26: -5 | M26: 14 | N26: 0 | O26: 0 | P26: 0 | Q26: 0 | R26: 0 | S26: 0 | T26: 0 | U26: 0 | V26: 0 | W26: 0 | X26: 0 | Y26: AFLAK2 | Z26: 0 | AA26: 0 | AB26: 0 | AC26: 0 | AD26: 0 | AE26: 0 | AF26: -3.36 | AG26: 0.56 | AH26: -0.4 | AI26: -3.76 | AL26: ch_3SmJRqGOs2bxG0Rw0PArymok | AM26: txn_3SmJRqGOs2bxG0Rw06xFWItU | AN26: Self Delivery / 3PL
A27: 06/01/2026 | B27: 06/01/2026 | C27: Chatham | D27: Delivery | E27: ASAP | F27: fulfilled | G27: NGGC5J | H27: 38.08 | I27: 38.08 | J27: 39.1 | K27: 0 | L27: -6.5 | M27: 32.6 | N27: 0 | O27: 1.49 | P27: 0.25 | Q27: 0 | R27: 0 | S27: -9.66 | T27: 1.61 | U27: 0 | V27: 0 | W27: 3.99 | X27: 5.67 | Y27: CRISPY6 | Z27: 0 | AA27: 0 | AB27: 0 | AC27: 3.99 | AD27: 0.66 | AE27: 5.67 | AF27: -7.83 | AG27: 1.3 | AH27: -0.73 | AI27: -18.22 | AK27: 65279e13-6864-4fe4-8011-ebc8e28c6f09 | AL27: ch_3SmdjJGOs2bxG0Rw08uchZ73 | AM27: txn_3SmdjJGOs2bxG0Rw0QAZpkQc | AN27: Slerp Courier Partner - Bike/Moped
A28: 07/01/2026 | B28: 07/01/2026 | C28: Loughton | D28: Delivery | E28: Scheduled same day | F28: fulfilled | G28: JBZ5EZ | H28: 24.73 | I28: 24.73 | J28: 17.75 | K28: 0 | L28: 0 | M28: 17.75 | N28: 0 | O28: 0.99 | P28: 0.16 | Q28: 0 | R28: 0 | S28: -11.34 | T28: 1.89 | U28: 0 | V28: 0 | W28: 5.99 | X28: 5.35 | Z28: 0 | AA28: 0 | AB28: 0 | AC28: 5.99 | AD28: 1 | AE28: 5.35 | AF28: -4.26 | AG28: 0.71 | AH28: -0.55 | AI28: -16.15 | AK28: fda9cb8e-cbb0-47ec-8d30-b54ee1e0990a | AL28: ch_3SmwM8GOs2bxG0Rw1DO0LVvm | AM28: txn_3SmwM8GOs2bxG0Rw15acbBwd | AN28: Slerp Courier Partner - Bike/Moped
A29: 07/01/2026 | B29: 07/01/2026 | C29: Loughton | D29: Pickup | E29: Scheduled same day | F29: fulfilled | G29: ADHFZQ | H29: 11.74 | I29: 11.74 | J29: 10.75 | K29: 0.02519685 | L29: 0 | M29: 10.75 | N29: 0 | O29: 0.99 | P29: 0.16 | Q29: 0 | R29: 0 | S29: 0 | T29: 0 | U29: 0 | V29: 0 | W29: 0 | X29: 0 | Z29: 0 | AA29: 0 | AB29: 0 | AC29: 0 | AD29: 0 | AE29: 0 | AF29: -2.58 | AG29: 0.43 | AH29: -0.36 | AI29: -2.94 | AL29: ch_3Sn0FmGOs2bxG0Rw0tJByc7N | AM29: txn_3Sn0FmGOs2bxG0Rw05JLiXL2 | AN29: Self Delivery / 3PL
A30: 07/01/2026 | B30: 07/01/2026 | C30: Loughton | D30: Delivery | E30: Scheduled same day | F30: fulfilled | G30: YRUGXW | H30: 15.63 | I30: 15.63 | J30: 11.65 | K30: 0 | L30: 0 | M30: 11.65 | N30: 0 | O30: 0.99 | P30: 0.16 | Q30: 0 | R30: 0 | S30: -7.98 | T30: 1.33 | U30: 0 | V30: 0 | W30: 2.99 | X30: 4.99 | Z30: 0 | AA30: 0 | AB30: 0 | AC30: 2.99 | AD30: 0.5 | AE30: 4.99 | AF30: -2.8 | AG30: 0.47 | AH30: -0.42 | AI30: -11.2 | AK30: 431dd96a-01f8-4bb5-8ecd-aa742bd887ce | AL30: ch_3Sn1UNGOs2bxG0Rw0WDragVp | AM30: txn_3Sn1UNGOs2bxG0Rw0rkCnysi | AN30: Slerp Courier Partner - Car/Van
A31: 07/01/2026 | B31: 07/01/2026 | C31: Loughton | D31: Pickup | E31: ASAP | F31: fulfilled | G31: HCW5QM | H31: 39.29 | I31: 39.29 | J31: 43.3 | K31: 0 | L31: -5 | M31: 38.3 | N31: 0 | O31: 0.99 | P31: 0.16 | Q31: 0 | R31: 0 | S31: 0 | T31: 0 | U31: 0 | V31: 0 | W31: 0 | X31: 0 | Y31: AQ3M6K | Z31: 0 | AA31: 0 | AB31: 0 | AC31: 0 | AD31: 0 | AE31: 0 | AF31: -9.2 | AG31: 1.53 | AH31: -0.75 | AI31: -9.95 | AL31: ch_3Sn1inGOs2bxG0Rw0Fgn08tn | AM31: txn_3Sn1inGOs2bxG0Rw0pAwUQDp | AN31: Self Delivery / 3PL
A32: 07/01/2026 | B32: 07/01/2026 | C32: Loughton | D32: Delivery | E32: ASAP | F32: fulfilled | G32: ATGQXV | H32: 19.63 | I32: 19.63 | J32: 15.65 | K32: 0 | L32: 0 | M32: 15.65 | N32: 0 | O32: 0.99 | P32: 0.16 | Q32: 0 | R32: 0 | S32: -7.98 | T32: 1.33 | U32: 0 | V32: 0 | W32: 2.99 | X32: 4.99 | Z32: 0 | AA32: 0 | AB32: 0 | AC32: 2.99 | AD32: 0.5 | AE32: 4.99 | AF32: -3.76 | AG32: 0.63 | AH32: -0.47 | AI32: -12.21 | AK32: d96c4a04-9d4c-435a-af05-c9e8843306d5 | AL32: ch_3Sn1sIGOs2bxG0Rw1zqT9Ar3 | AM32: txn_3Sn1sIGOs2bxG0Rw1A27EZuz | AN32: Slerp Courier Partner - Bike/Moped
A33: 07/01/2026 | B33: 07/01/2026 | C33: Loughton | D33: Delivery | E33: ASAP | F33: fulfilled | G33: AGQCW3 | H33: 29.98 | I33: 29.98 | J33: 32.5 | K33: 0 | L33: -6.5 | M33: 26 | N33: 0 | O33: 0.99 | P33: 0.16 | Q33: 0 | R33: 0 | S33: -7.98 | T33: 1.33 | U33: 0 | V33: 0 | W33: 2.99 | X33: 4.99 | Y33: CRISPY6 | Z33: 0 | AA33: 0 | AB33: 0 | AC33: 2.99 | AD33: 0.5 | AE33: 4.99 | AF33: -6.24 | AG33: 1.04 | AH33: -0.62 | AI33: -14.84 | AK33: e5e46ba8-8a46-48f0-8e40-8a2338c15ce8 | AL33: ch_3Sn1vsGOs2bxG0Rw0Tm8i6nv | AM33: txn_3Sn1vsGOs2bxG0Rw06YB7u3B | AN33: Slerp Courier Partner - Bike/Moped
A34: 07/01/2026 | B34: 07/01/2026 | C34: Loughton | D34: Delivery | E34: ASAP | F34: fulfilled | G34: XRU7PR | H34: 23.48 | I34: 23.48 | J34: 22.95 | K34: 0 | L34: -3.45 | M34: 19.5 | N34: 0 | O34: 0.99 | P34: 0.16 | Q34: 0 | R34: 0 | S34: -7.98 | T34: 1.33 | U34: 0 | V34: 0 | W34: 2.99 | X34: 4.99 | Y34: H66ADR | Z34: 0 | AA34: 0 | AB34: 0 | AC34: 2.99 | AD34: 0.5 | AE34: 4.99 | AF34: -4.68 | AG34: 0.78 | AH34: -0.53 | AI34: -13.19 | AK34: ef938c78-c2a3-446e-a45e-4b62e09c5914 | AL34: ch_3Sn2NnGOs2bxG0Rw1rSVHlrx | AM34: txn_3Sn2NnGOs2bxG0Rw1dJQtPiE | AN34: Slerp Courier Partner - Bike/Moped
A35: 07/01/2026 | B35: 07/01/2026 | C35: Loughton | D35: Pickup | E35: ASAP | F35: fulfilled | G35: QTV7GG | H35: 14.94 | I35: 14.94 | J35: 13.95 | K35: 0 | L35: 0 | M35: 13.95 | N35: 0 | O35: 0.99 | P35: 0.16 | Q35: 0 | R35: 0 | S35: 0 | T35: 0 | U35: 0 | V35: 0 | W35: 0 | X35: 0 | Z35: 0 | AA35: 0 | AB35: 0 | AC35: 0 | AD35: 0 | AE35: 0 | AF35: -3.35 | AG35: 0.56 | AH35: -0.41 | AI35: -3.76 | AL35: ch_3Sn2ORGOs2bxG0Rw0NKqG77T | AM35: txn_3Sn2ORGOs2bxG0Rw0DfVBbtF | AN35: Self Delivery / 3PL
A36: 08/01/2026 | B36: 08/01/2026 | C36: Loughton | D36: Pickup | E36: Scheduled same day | F36: fulfilled | G36: TPWY4Q | H36: 28.89 | I36: 28.89 | J36: 27.9 | K36: 0 | L36: 0 | M36: 27.9 | N36: 0 | O36: 0.99 | P36: 0.16 | Q36: 0 | R36: 0 | S36: 0 | T36: 0 | U36: 0 | V36: 0 | W36: 0 | X36: 0 | Z36: 0 | AA36: 0 | AB36: 0 | AC36: 0 | AD36: 0 | AE36: 0 | AF36: -6.7 | AG36: 1.12 | AH36: -0.6 | AI36: -7.3 | AL36: ch_3SnPMuGOs2bxG0Rw0vOmWcst | AM36: txn_3SnPMuGOs2bxG0Rw0zFMiLil | AN36: Self Delivery / 3PL
A37: 10/01/2026 | B37: 10/01/2026 | C37: Loughton | D37: Pickup | E37: ASAP | F37: fulfilled | G37: DLKEUX | H37: 23.44 | I37: 23.44 | J37: 30.45 | K37: 0 | L37: -8 | M37: 22.45 | N37: 0 | O37: 0.99 | P37: 0.16 | Q37: 0 | R37: 0 | S37: 0 | T37: 0 | U37: 0 | V37: 0 | W37: 0 | X37: 0 | Y37: SPEND30SAVE802 | Z37: 0 | AA37: 0 | AB37: 0 | AC37: 0 | AD37: 0 | AE37: 0 | AF37: -5.39 | AG37: 0.9 | AH37: -0.88 | AI37: -6.27 | AL37: ch_3So8MKGOs2bxG0Rw108qvya2 | AM37: txn_3So8MKGOs2bxG0Rw1YnoUkjQ | AN37: Self Delivery / 3PL
A38: 10/01/2026 | B38: 10/01/2026 | C38: Loughton | D38: Pickup | E38: Scheduled same day | F38: fulfilled | G38: ZP3U5F | H38: 24.29 | I38: 24.29 | J38: 31.3 | K38: 0 | L38: -8 | M38: 23.3 | N38: 0 | O38: 0.99 | P38: 0.16 | Q38: 0 | R38: 0 | S38: 0 | T38: 0 | U38: 0 | V38: 0 | W38: 0 | X38: 0 | Y38: SPEND30SAVE802 | Z38: 0 | AA38: 0 | AB38: 0 | AC38: 0 | AD38: 0 | AE38: 0 | AF38: -5.6 | AG38: 0.93 | AH38: -0.54 | AI38: -6.14 | AL38: ch_3So8bZGOs2bxG0Rw1KQX6TTp | AM38: txn_3So8bZGOs2bxG0Rw1swRHRx5 | AN38: Self Delivery / 3PL
A39: 11/01/2026 | B39: 11/01/2026 | C39: Loughton | D39: Pickup | E39: ASAP | F39: fulfilled | G39: CG3L6L | H39: 28.89 | I39: 28.89 | J39: 27.9 | K39: 0 | L39: 0 | M39: 27.9 | N39: 0 | O39: 0.99 | P39: 0.16 | Q39: 0 | R39: 0 | S39: 0 | T39: 0 | U39: 0 | V39: 0 | W39: 0 | X39: 0 | Z39: 0 | AA39: 0 | AB39: 0 | AC39: 0 | AD39: 0 | AE39: 0 | AF39: -6.7 | AG39: 1.12 | AH39: -0.6 | AI39: -7.3 | AL39: ch_3SoUl5GOs2bxG0Rw0QsgC5w5 | AM39: txn_3SoUl5GOs2bxG0Rw0vio2Mui | AN39: Self Delivery / 3PL
A40: 11/01/2026 | B40: 11/01/2026 | C40: Loughton | D40: Pickup | E40: ASAP | F40: fulfilled | G40: 2MPJ7B | H40: 8.44 | I40: 8.44 | J40: 13.95 | K40: 0 | L40: -6.5 | M40: 7.45 | N40: 0 | O40: 0.99 | P40: 0.16 | Q40: 0 | R40: 0 | S40: 0 | T40: 0 | U40: 0 | V40: 0 | W40: 0 | X40: 0 | Y40: CRISPY6 | Z40: 0 | AA40: 0 | AB40: 0 | AC40: 0 | AD40: 0 | AE40: 0 | AF40: -1.79 | AG40: 0.3 | AH40: -0.44 | AI40: -2.23 | AL40: ch_3SoV8hGOs2bxG0Rw19wz4noB | AM40: txn_3SoV8hGOs2bxG0Rw1V5n7cOy | AN40: Self Delivery / 3PL
A41: 11/01/2026 | B41: 11/01/2026 | C41: Loughton | D41: Pickup | E41: ASAP | F41: fulfilled | G41: GMGESW | H41: 25.84 | I41: 25.84 | J41: 32.85 | K41: 0 | L41: -8 | M41: 24.85 | N41: 0 | O41: 0.99 | P41: 0.16 | Q41: 0 | R41: 0 | S41: 0 | T41: 0 | U41: 0 | V41: 0 | W41: 0 | X41: 0 | Y41: SPEND30SAVE802 | Z41: 0 | AA41: 0 | AB41: 0 | AC41: 0 | AD41: 0 | AE41: 0 | AF41: -5.97 | AG41: 1 | AH41: -0.95 | AI41: -6.92 | AL41: ch_3SoVHtGOs2bxG0Rw0tAig5Dx | AM41: txn_3SoVHtGOs2bxG0Rw0CgEnyzu | AN41: Self Delivery / 3PL
A42: 12/01/2026 | B42: 12/01/2026 | C42: Loughton | D42: Pickup | E42: ASAP | F42: fulfilled | G42: 4PKYLR | H42: 14.89 | I42: 14.89 | J42: 18.9 | K42: 0 | L42: -5 | M42: 13.9 | N42: 0 | O42: 0.99 | P42: 0.16 | Q42: 0 | R42: 0 | S42: 0 | T42: 0 | U42: 0 | V42: 0 | W42: 0 | X42: 0 | Y42: RUUDTG | Z42: 0 | AA42: 0 | AB42: 0 | AC42: 0 | AD42: 0 | AE42: 0 | AF42: -3.34 | AG42: 0.56 | AH42: -0.41 | AI42: -3.75 | AL42: ch_3SopoxGOs2bxG0Rw0oYHRWpt | AM42: txn_3SopoxGOs2bxG0Rw0Ybjme2N | AN42: Self Delivery / 3PL
A43: 12/01/2026 | B43: 12/01/2026 | C43: Loughton | D43: Delivery | E43: ASAP | F43: fulfilled | G43: VJSJJW | H43: 18.88 | I43: 18.88 | J43: 14.9 | K43: 0 | L43: 0 | M43: 14.9 | N43: 0 | O43: 0.99 | P43: 0.16 | Q43: 0 | R43: 0 | S43: -8.82 | T43: 1.47 | U43: 0 | V43: 0 | W43: 2.99 | X43: 5.83 | Z43: 0 | AA43: 0 | AB43: 0 | AC43: 2.99 | AD43: 0.5 | AE43: 5.83 | AF43: -3.58 | AG43: 0.6 | AH43: -0.46 | AI43: -12.86 | AK43: cb32eb4f-6a0b-4373-bea6-32dfeeb8d325 | AL43: ch_3Soqj4GOs2bxG0Rw161lPm9x | AM43: txn_3Soqj4GOs2bxG0Rw1SU4tIo5 | AN43: Slerp Courier Partner - Car/Van
A44: 14/01/2026 | B44: 14/01/2026 | C44: Maidstone | D44: Pickup | E44: Scheduled same day | F44: fulfilled | G44: VZMNAW | H44: 13 | I44: 13 | J44: 13 | K44: 0 | L44: 0 | M44: 13 | N44: 0 | O44: 0 | P44: 0 | Q44: 0 | R44: 0 | S44: 0 | T44: 0 | U44: 0 | V44: 0 | W44: 0 | X44: 0 | Z44: 0 | AA44: 0 | AB44: 0 | AC44: 0 | AD44: 0 | AE44: 0 | AF44: -3.12 | AG44: 0.52 | AH44: -0.38 | AI44: -3.5 | AL44: ch_3SpTjCGOs2bxG0Rw1cg06jpR | AM44: txn_3SpTjCGOs2bxG0Rw1XOnUky2 | AN44: Self Delivery / 3PL
A45: 14/01/2026 | B45: 14/01/2026 | C45: Loughton | D45: Delivery | E45: Scheduled same day | F45: fulfilled | G45: JTKQPZ | H45: 19.98 | I45: 19.98 | J45: 17.75 | K45: 0 | L45: -4.75 | M45: 13 | N45: 0 | O45: 0.99 | P45: 0.16 | Q45: 0 | R45: 0 | S45: -11.34 | T45: 1.89 | U45: 0 | V45: 0 | W45: 5.99 | X45: 5.35 | Y45: Q7V2T7 | Z45: 0 | AA45: 0 | AB45: 0 | AC45: 5.99 | AD45: 1 | AE45: 5.35 | AF45: -3.12 | AG45: 0.52 | AH45: -0.48 | AI45: -14.94 | AK45: 850d4d22-002a-4eff-8d4f-013e9844ccd8 | AL45: ch_3SpTpBGOs2bxG0Rw15p1pdvu | AM45: txn_3SpTpBGOs2bxG0Rw1INIlsi3 | AN45: Slerp Courier Partner - Bike/Moped
...

Sheet Summary
A1: This is a summary based on your download. Please note the period it reflects.
A2: This is not a VAT invoice. To see invoices and receipts, please login in to Controls > Settings > Accounts & Billing
D4: Generated on: 14 February 2026
A6: Period: | D6: January 1 to January 31
A9: Company name: | D9: Wing Shack Co
B10: NET | C10: VAT paid for Slerp | D10: Total
A11: Slerp Fees & Charges
A12: Slerp Commissions: | B12: =D12/1.2 | C12: =B12*0.2 | D12: =-'2026-01-01 to 2026-01-31'!C14
A13: Payment Fees (no VAT applicable): | B13: =D13 | C13: =0 | D13: =-'2026-01-01 to 2026-01-31'!C16
A14: Slerp Courier Partner Fees: | B14: =D14/1.2 | C14: =B14*0.2 | D14: =-'2026-01-01 to 2026-01-31'!C15
A15: Total Fees & Charges | B15: =SUM(B12:B14) | C15: =SUM(C12:C14) | D15: =SUM(D12:D14)
A17: Goods and Services | B17: NET | C17: VAT Collected | D17: Total
A18: Products: | B18: =D18-C18 | C18: ='2026-01-01 to 2026-01-31'!K90+'2026-01-01 to 2026-01-31'!K105 | D18: ='2026-01-01 to 2026-01-31'!M90+'2026-01-01 to 2026-01-31'!M105
A19: Self-delivery / Self-organised fees: | B19: =D19-C19 | C19: =SUM('2026-01-01 to 2026-01-31'!V90, '2026-01-01 to 2026-01-31'!V105) | D19: =-SUM('2026-01-01 to 2026-01-31'!U90, '2026-01-01 to 2026-01-31'!U105)
A20: Additional store fee: | B20: =D20-C20 | C20: =SUM('2026-01-01 to 2026-01-31'!P90, '2026-01-01 to 2026-01-31'!P105) | D20: =SUM('2026-01-01 to 2026-01-31'!O90, '2026-01-01 to 2026-01-31'!O105)
A21: Total Goods and Services: | B21: =SUM(B18:B20) | C21: =SUM(C18:C20) | D21: =SUM(D18:D20)
C27: Total VAT paid for Slerp | D27: =C15
C28: Total Vat Collected from End-Customer | D28: =C20
A30: *Figures may change based on when the Statement is generated as order statuses change. I.e. Refunds
A31: **Figures exclude fully refunded orders, additional post-transaction charges (i.e. additional courier charges), as well as monthly SaaS charges.
